2023-08-23 16:57:03 - INFO - [base_logger.py : 34] :: Initialized logger for the service [authtoken] :: [SUCCESS]
2023-08-23 16:57:03 - INFO - [create_app.py : 42] :: Received Service [authtoken]
2023-08-23 16:57:03 - INFO - [create_app.py : 44] :: Flask of Application Instance created for service [authtoken] ,  App Name :: [<Flask 'authtoken'>] ==> SUCCESS
2023-08-23 16:57:03 - INFO - [create_app.py : 53] :: Created Blueprint :: <Blueprint 'authtoken_bp'> for the Application service ::authtoken
2023-08-23 16:57:03 - INFO - [create_app.py : 70] :: Added Blueprints :: /static/<path:filename>
2023-08-23 16:57:03 - INFO - [create_app.py : 80] :: Creating DB-Engine using DatabaseURI for Service :: [authtoken]
2023-08-23 16:57:03 - INFO - [create_app.py : 74] :: Preparing DatabaseURI for Service :: [authtoken]
2023-08-23 16:57:03 - INFO - [create_app.py : 76] :: Prepared DatabaseURI for Service :: [authtoken] - mysql+pymysql://root:Ishi#06041995@127.0.0.1:3305/AUTHTOKENS
2023-08-23 16:57:03 - INFO - [create_app.py : 82] :: Created DB-Engine using DatabaseURIfor Service :: [Engine(mysql+pymysql://root:***@127.0.0.1:3305/AUTHTOKENS)]
2023-08-23 16:57:03 - INFO - [create_app.py : 111] :: Current Connection status set to :: False for the service :: authtoken
2023-08-23 16:57:03 - INFO - [create_app.py : 112] :: Trying to establish the connection to the database :: [IN-PROGRESS]
2023-08-23 16:57:03 - INFO - [create_app.py : 116] :: Established the connection to the database :: [SUCCESS]
2023-08-23 16:57:03 - INFO - [create_app.py : 118] :: Current Connection status set to :: True for the service :: authtoken
2023-08-23 16:57:03 - INFO - [create_app.py : 120] :: Closing the Current Connection as the connection was established for the service :: authtoken
2023-08-23 16:57:03 - INFO - [create_app.py : 153] :: Database already exists :: AUTHTOKENS
2023-08-23 16:57:03 - INFO - [create_app.py : 129] :: Trying to create the tables if not present in the database...
2023-08-23 16:57:03 - INFO - [create_app.py : 131] :: Going to create the tables ...
2023-08-23 16:57:03 - INFO - [create_app.py : 134] :: Created the tables ...
2023-08-23 16:57:03 - INFO - [create_app.py : 87] :: Binding SQLALCHEMY using DatabaseURI:: [mysql+pymysql://root:Ishi#06041995@127.0.0.1:3305/AUTHTOKENS] to Application Instance for Service :: [authtoken]
2023-08-23 16:57:03 - INFO - [create_app.py : 89] :: Binded SQLALCHEMY :: [<SQLAlchemy>] to Application Instance for Service :: [authtoken]
2023-08-23 16:57:03 - INFO - [create_app.py : 93] :: Initialized Pool for Service ==>[authtoken] :: [SUCCESS]
2023-08-23 16:57:03 - INFO - [create_app.py : 162] :: #---------------------------------[ POOL - INFO ]----------------------------------------#
2023-08-23 16:57:03 - INFO - [create_app.py : 163] :: Displaying Pool_Info for Service ==>[authtoken] 
2023-08-23 16:57:03 - INFO - [create_app.py : 164] :: Current Pool Info :: <sqlalchemy.pool.impl.QueuePool object at 0x108316fd0> - ID: 4432424912
2023-08-23 16:57:03 - INFO - [create_app.py : 165] :: Current Pool Size ::  100
2023-08-23 16:57:03 - INFO - [create_app.py : 166] :: Checked Out Connections from Pool  0
2023-08-23 16:57:03 - INFO - [create_app.py : 167] :: Checked in Connections available in Pool :: 0
2023-08-23 16:57:03 - INFO - [create_app.py : 168] :: Current Pool Overflow Info :: -100
2023-08-23 16:57:03 - INFO - [create_app.py : 169] :: #---------------------------------[ POOL - INFO ]----------------------------------------#
2023-08-23 16:57:03 - INFO - [create_app.py : 57] :: Registering blueprints to the service :: <Flask 'authtoken'>
2023-08-23 16:57:03 - INFO - [create_app.py : 70] :: Added Blueprints :: /static/<path:filename>
2023-08-23 16:57:03 - INFO - [create_app.py : 70] :: Added Blueprints :: /api/v1/airliner/generateToken
2023-08-23 16:57:03 - INFO - [create_app.py : 61] :: Registering Error Handler 500-<function internal_server_error at 0x109031040> to the service :: <Flask 'authtoken'>
2023-08-23 16:57:03 - INFO - [create_app.py : 61] :: Registering Error Handler 400-<function bad_request at 0x10902b9d0> to the service :: <Flask 'authtoken'>
2023-08-23 16:57:03 - INFO - [create_app.py : 61] :: Registering Error Handler 404-<function not_found at 0x1090310d0> to the service :: <Flask 'authtoken'>
2023-08-23 16:57:03 - INFO - [create_app.py : 66] :: Error Code: None, Handler Function: {}
2023-08-23 16:57:03 - INFO - [token_app.py : 5] :: Started the AUTH TOKEN server ...
2023-08-23 16:57:03 - INFO - [token_app.py : 6] :: Application is ready to server traffic.
2023-08-23 16:57:11 - INFO - [authtoken_controller.py : 15] :: REQUEST ==> Received Endpoint :: authtoken_bp.create_token
2023-08-23 16:57:11 - INFO - [authtoken_controller.py : 17] :: Received Headers from the request :: {'Content-Type': 'application/json', 'User-Agent': 'PostmanRuntime/7.32.3', 'Accept': '*/*', 'Host': '127.0.0.1:9092', 'Accept-Encoding': 'gzip, deflate, br', 'Connection': 'keep-alive', 'Content-Length': '81'}
2023-08-23 16:57:11 - INFO - [authtoken_controller.py : 18] :: Validation for Request-Header is  :: [STARTED]
2023-08-23 16:57:11 - INFO - [authtoken_controller.py : 21] :: Validation for Request-Header is  :: [SUCCESS]
2023-08-23 16:57:11 - INFO - [authtoken_controller.py : 24] :: Validation for Request-Body is  :: [STARTED]
2023-08-23 16:57:11 - INFO - [authtoken_controller.py : 30] :: Validating whether it is registered user  :: [STARTED]
2023-08-23 16:57:11 - INFO - [authtoken_controller.py : 31] :: Sending gRPC message to Registration Service :: [STARTED]
2023-08-23 16:57:11 - INFO - [client.py : 14] :: Request Created  :: userid: "33"
username: "kamal4"
passcode: "Ishi#06041995"

2023-08-23 16:57:11 - INFO - [client.py : 27] :: Created channel :: <grpc._channel.Channel object at 0x10908f190>
2023-08-23 16:57:11 - INFO - [client.py : 29] :: Created Stub and assigned to the channel :: <src.airliner_grpc.token_pb2_grpc.UserValidationForTokenGenerationStub object at 0x1090bcc40>
2023-08-23 16:57:11 - ERROR - [client.py : 44] :: Error occurred :: UNKNOWN:failed to connect to all addresses; last error: UNKNOWN: ipv4:127.0.0.1:8081: Failed to connect to remote host: Connection refused {created_time:"2023-08-23T16:57:11.902953-07:00", grpc_status:14}	Line No:: 40
2023-08-23 16:57:11 - INFO - [authtoken_controller.py : 37] :: gRPC Response data :: None, Response status :: False
2023-08-23 16:57:11 - ERROR - [authtoken_controller.py : 75] :: Sending gRPC message to Registration Service :: [FAILED]
2023-08-23 16:57:11 - INFO - [authtoken_controller.py : 78] :: Sending Error response back to client :: {'message': 'Failure to establish gRPC connection'}
