2023-08-29 17:06:37 - INFO - [base_logger.py : create_logger_for_service - 30] :: Initialized logger for the service [authtoken] :: [SUCCESS]
2023-08-29 17:06:37 - INFO - [create_app.py : create_app_instance - 61] :: Received Service [authtoken]
2023-08-29 17:06:37 - INFO - [create_app.py : create_app_instance - 63] :: Flask of Application Instance created for service [authtoken] ,  App Name :: [<Flask 'authtoken'>] ==> SUCCESS
2023-08-29 17:06:37 - INFO - [create_app.py : read_json_schema - 285] :: Received Schema File Path : /Users/kamalsaidevarapalli/Desktop/Workshop/AirlinerAdminstration/src/authtoken_service/schemas/headers/gentoken_headers_schema.json
2023-08-29 17:06:37 - INFO - [create_app.py : read_json_schema - 295] :: Schema Validation True
2023-08-29 17:06:37 - INFO - [create_app.py : read_json_schema - 285] :: Received Schema File Path : /Users/kamalsaidevarapalli/Desktop/Workshop/AirlinerAdminstration/src/authtoken_service/schemas/requests/generate_token/req_schema.json
2023-08-29 17:06:37 - INFO - [create_app.py : read_json_schema - 295] :: Schema Validation True
2023-08-29 17:06:37 - INFO - [create_app.py : create_blueprint - 79] :: Created Blueprint :: <Blueprint 'authtoken_bp'> for the Application service ::authtoken
2023-08-29 17:06:37 - INFO - [create_app.py : display_registered_blueprints_for_service - 111] :: Added Blueprints :: /static/<path:filename>
2023-08-29 17:06:37 - INFO - [create_app.py : create_db_engine - 131] :: Creating DB-Engine using DatabaseURI for Service :: [authtoken]
2023-08-29 17:06:37 - INFO - [create_app.py : get_database_uri - 120] :: Preparing DatabaseURI for Service :: [authtoken]
2023-08-29 17:06:37 - INFO - [create_app.py : get_database_uri - 122] :: Prepared DatabaseURI for Service :: [authtoken] - postgresql://airlineradmin:Ishi%2306041995@authtoken-db:5432/AUTHTOKENS
2023-08-29 17:06:37 - INFO - [create_app.py : create_db_engine - 136] :: Created DB-Engine using DatabaseURI for Service :: [Engine(postgresql://airlineradmin:***@authtoken-db:5432/AUTHTOKENS)]
2023-08-29 17:06:37 - INFO - [create_app.py : check_database_connectivity - 235] :: Current Connection status set to :: False for the service :: authtoken
2023-08-29 17:06:37 - INFO - [create_app.py : check_database_connectivity - 236] :: Trying to establish the connection to the database :: [IN-PROGRESS]
2023-08-29 17:06:37 - ERROR - [create_app.py : check_database_connectivity - 246] :: Current Connection status set to :: False
2023-08-29 17:06:37 - INFO - [create_app.py : check_db_connectivity_and_retry - 230] :: Going for retry .. RETRY_INTERVAL :: 5 sec
2023-08-29 17:06:42 - INFO - [create_app.py : check_database_connectivity - 235] :: Current Connection status set to :: False for the service :: authtoken
2023-08-29 17:06:42 - INFO - [create_app.py : check_database_connectivity - 236] :: Trying to establish the connection to the database :: [IN-PROGRESS]
2023-08-29 17:06:42 - ERROR - [create_app.py : check_database_connectivity - 246] :: Current Connection status set to :: False
2023-08-29 17:06:42 - INFO - [create_app.py : check_db_connectivity_and_retry - 230] :: Going for retry .. RETRY_INTERVAL :: 5 sec
2023-08-29 17:06:47 - INFO - [create_app.py : check_database_connectivity - 235] :: Current Connection status set to :: False for the service :: authtoken
2023-08-29 17:06:47 - INFO - [create_app.py : check_database_connectivity - 236] :: Trying to establish the connection to the database :: [IN-PROGRESS]
2023-08-29 17:06:47 - ERROR - [create_app.py : check_database_connectivity - 246] :: Current Connection status set to :: False
2023-08-29 17:06:47 - INFO - [create_app.py : check_db_connectivity_and_retry - 230] :: Going for retry .. RETRY_INTERVAL :: 5 sec
2023-08-29 17:06:52 - INFO - [create_app.py : check_database_connectivity - 235] :: Current Connection status set to :: False for the service :: authtoken
2023-08-29 17:06:52 - INFO - [create_app.py : check_database_connectivity - 236] :: Trying to establish the connection to the database :: [IN-PROGRESS]
2023-08-29 17:06:52 - ERROR - [create_app.py : check_database_connectivity - 246] :: Current Connection status set to :: False
2023-08-29 17:06:52 - INFO - [create_app.py : check_db_connectivity_and_retry - 230] :: Going for retry .. RETRY_INTERVAL :: 5 sec
2023-08-29 17:06:57 - INFO - [create_app.py : check_database_connectivity - 235] :: Current Connection status set to :: False for the service :: authtoken
2023-08-29 17:06:57 - INFO - [create_app.py : check_database_connectivity - 236] :: Trying to establish the connection to the database :: [IN-PROGRESS]
2023-08-29 17:06:57 - ERROR - [create_app.py : check_database_connectivity - 246] :: Current Connection status set to :: False
2023-08-29 17:06:57 - INFO - [create_app.py : check_db_connectivity_and_retry - 230] :: Going for retry .. RETRY_INTERVAL :: 5 sec
2023-08-29 17:07:02 - INFO - [create_app.py : check_database_connectivity - 235] :: Current Connection status set to :: False for the service :: authtoken
2023-08-29 17:07:02 - INFO - [create_app.py : check_database_connectivity - 236] :: Trying to establish the connection to the database :: [IN-PROGRESS]
2023-08-29 17:07:02 - ERROR - [create_app.py : check_database_connectivity - 246] :: Current Connection status set to :: False
2023-08-29 17:07:02 - INFO - [create_app.py : check_db_connectivity_and_retry - 230] :: Going for retry .. RETRY_INTERVAL :: 5 sec
2023-08-29 17:07:07 - INFO - [create_app.py : check_database_connectivity - 235] :: Current Connection status set to :: False for the service :: authtoken
2023-08-29 17:07:07 - INFO - [create_app.py : check_database_connectivity - 236] :: Trying to establish the connection to the database :: [IN-PROGRESS]
2023-08-29 17:07:07 - ERROR - [create_app.py : check_database_connectivity - 246] :: Current Connection status set to :: False
2023-08-29 17:07:07 - INFO - [create_app.py : check_db_connectivity_and_retry - 230] :: Going for retry .. RETRY_INTERVAL :: 5 sec
2023-08-29 17:07:12 - INFO - [create_app.py : check_database_connectivity - 235] :: Current Connection status set to :: False for the service :: authtoken
2023-08-29 17:07:12 - INFO - [create_app.py : check_database_connectivity - 236] :: Trying to establish the connection to the database :: [IN-PROGRESS]
2023-08-29 17:07:12 - ERROR - [create_app.py : check_database_connectivity - 246] :: Current Connection status set to :: False
2023-08-29 17:07:12 - INFO - [create_app.py : check_db_connectivity_and_retry - 230] :: Going for retry .. RETRY_INTERVAL :: 5 sec
2023-08-29 17:07:17 - INFO - [create_app.py : check_database_connectivity - 235] :: Current Connection status set to :: False for the service :: authtoken
2023-08-29 17:07:17 - INFO - [create_app.py : check_database_connectivity - 236] :: Trying to establish the connection to the database :: [IN-PROGRESS]
2023-08-29 17:07:17 - ERROR - [create_app.py : check_database_connectivity - 246] :: Current Connection status set to :: False
2023-08-29 17:07:17 - INFO - [create_app.py : check_db_connectivity_and_retry - 230] :: Going for retry .. RETRY_INTERVAL :: 5 sec
2023-08-29 17:07:22 - INFO - [create_app.py : check_database_connectivity - 235] :: Current Connection status set to :: False for the service :: authtoken
2023-08-29 17:07:22 - INFO - [create_app.py : check_database_connectivity - 236] :: Trying to establish the connection to the database :: [IN-PROGRESS]
2023-08-29 17:07:22 - ERROR - [create_app.py : check_database_connectivity - 246] :: Current Connection status set to :: False
2023-08-29 17:07:22 - INFO - [create_app.py : check_db_connectivity_and_retry - 230] :: Going for retry .. RETRY_INTERVAL :: 5 sec
2023-08-29 17:07:27 - INFO - [create_app.py : check_database_connectivity - 235] :: Current Connection status set to :: False for the service :: authtoken
2023-08-29 17:07:27 - INFO - [create_app.py : check_database_connectivity - 236] :: Trying to establish the connection to the database :: [IN-PROGRESS]
2023-08-29 17:07:27 - ERROR - [create_app.py : check_database_connectivity - 246] :: Current Connection status set to :: False
2023-08-29 17:07:27 - INFO - [create_app.py : check_db_connectivity_and_retry - 230] :: Going for retry .. RETRY_INTERVAL :: 5 sec
2023-08-29 17:07:32 - INFO - [create_app.py : check_database_connectivity - 235] :: Current Connection status set to :: False for the service :: authtoken
2023-08-29 17:07:32 - INFO - [create_app.py : check_database_connectivity - 236] :: Trying to establish the connection to the database :: [IN-PROGRESS]
2023-08-29 17:07:32 - ERROR - [create_app.py : check_database_connectivity - 246] :: Current Connection status set to :: False
2023-08-29 17:07:32 - INFO - [create_app.py : check_db_connectivity_and_retry - 230] :: Going for retry .. RETRY_INTERVAL :: 5 sec
2023-08-29 17:07:37 - INFO - [create_app.py : check_database_connectivity - 235] :: Current Connection status set to :: False for the service :: authtoken
2023-08-29 17:07:37 - INFO - [create_app.py : check_database_connectivity - 236] :: Trying to establish the connection to the database :: [IN-PROGRESS]
2023-08-29 17:07:37 - ERROR - [create_app.py : check_database_connectivity - 246] :: Current Connection status set to :: False
2023-08-29 17:07:37 - INFO - [create_app.py : check_db_connectivity_and_retry - 230] :: Going for retry .. RETRY_INTERVAL :: 5 sec
2023-08-29 17:07:42 - INFO - [create_app.py : check_database_connectivity - 235] :: Current Connection status set to :: False for the service :: authtoken
2023-08-29 17:07:42 - INFO - [create_app.py : check_database_connectivity - 236] :: Trying to establish the connection to the database :: [IN-PROGRESS]
2023-08-29 17:07:42 - ERROR - [create_app.py : check_database_connectivity - 246] :: Current Connection status set to :: False
2023-08-29 17:07:42 - INFO - [create_app.py : check_db_connectivity_and_retry - 230] :: Going for retry .. RETRY_INTERVAL :: 5 sec
2023-08-29 17:07:47 - INFO - [create_app.py : check_database_connectivity - 235] :: Current Connection status set to :: False for the service :: authtoken
2023-08-29 17:07:47 - INFO - [create_app.py : check_database_connectivity - 236] :: Trying to establish the connection to the database :: [IN-PROGRESS]
2023-08-29 17:07:47 - ERROR - [create_app.py : check_database_connectivity - 246] :: Current Connection status set to :: False
2023-08-29 17:07:47 - INFO - [create_app.py : check_db_connectivity_and_retry - 230] :: Going for retry .. RETRY_INTERVAL :: 5 sec
2023-08-29 17:07:52 - INFO - [create_app.py : check_database_connectivity - 235] :: Current Connection status set to :: False for the service :: authtoken
2023-08-29 17:07:52 - INFO - [create_app.py : check_database_connectivity - 236] :: Trying to establish the connection to the database :: [IN-PROGRESS]
2023-08-29 17:07:52 - ERROR - [create_app.py : check_database_connectivity - 246] :: Current Connection status set to :: False
2023-08-29 17:07:52 - INFO - [create_app.py : check_db_connectivity_and_retry - 230] :: Going for retry .. RETRY_INTERVAL :: 5 sec
2023-08-29 17:07:57 - INFO - [create_app.py : check_database_connectivity - 235] :: Current Connection status set to :: False for the service :: authtoken
2023-08-29 17:07:57 - INFO - [create_app.py : check_database_connectivity - 236] :: Trying to establish the connection to the database :: [IN-PROGRESS]
2023-08-29 17:07:57 - ERROR - [create_app.py : check_database_connectivity - 246] :: Current Connection status set to :: False
2023-08-29 17:07:57 - INFO - [create_app.py : check_db_connectivity_and_retry - 230] :: Going for retry .. RETRY_INTERVAL :: 5 sec
2023-08-29 17:08:02 - INFO - [create_app.py : check_database_connectivity - 235] :: Current Connection status set to :: False for the service :: authtoken
2023-08-29 17:08:02 - INFO - [create_app.py : check_database_connectivity - 236] :: Trying to establish the connection to the database :: [IN-PROGRESS]
2023-08-29 17:08:02 - ERROR - [create_app.py : check_database_connectivity - 246] :: Current Connection status set to :: False
2023-08-29 17:08:02 - INFO - [create_app.py : check_db_connectivity_and_retry - 230] :: Going for retry .. RETRY_INTERVAL :: 5 sec
2023-08-29 17:08:07 - INFO - [create_app.py : check_database_connectivity - 235] :: Current Connection status set to :: False for the service :: authtoken
2023-08-29 17:08:07 - INFO - [create_app.py : check_database_connectivity - 236] :: Trying to establish the connection to the database :: [IN-PROGRESS]
2023-08-29 17:08:07 - ERROR - [create_app.py : check_database_connectivity - 246] :: Current Connection status set to :: False
2023-08-29 17:08:07 - INFO - [create_app.py : check_db_connectivity_and_retry - 230] :: Going for retry .. RETRY_INTERVAL :: 5 sec
2023-08-29 17:08:12 - INFO - [create_app.py : check_database_connectivity - 235] :: Current Connection status set to :: False for the service :: authtoken
2023-08-29 17:08:12 - INFO - [create_app.py : check_database_connectivity - 236] :: Trying to establish the connection to the database :: [IN-PROGRESS]
2023-08-29 17:08:12 - ERROR - [create_app.py : check_database_connectivity - 246] :: Current Connection status set to :: False
2023-08-29 17:08:12 - INFO - [create_app.py : check_db_connectivity_and_retry - 230] :: Going for retry .. RETRY_INTERVAL :: 5 sec
2023-08-29 17:08:17 - INFO - [create_app.py : check_database_connectivity - 235] :: Current Connection status set to :: False for the service :: authtoken
2023-08-29 17:08:17 - INFO - [create_app.py : check_database_connectivity - 236] :: Trying to establish the connection to the database :: [IN-PROGRESS]
2023-08-29 17:08:17 - ERROR - [create_app.py : check_database_connectivity - 246] :: Current Connection status set to :: False
2023-08-29 17:08:17 - INFO - [create_app.py : check_db_connectivity_and_retry - 230] :: Going for retry .. RETRY_INTERVAL :: 5 sec
2023-08-29 17:08:22 - INFO - [create_app.py : check_database_connectivity - 235] :: Current Connection status set to :: False for the service :: authtoken
2023-08-29 17:08:22 - INFO - [create_app.py : check_database_connectivity - 236] :: Trying to establish the connection to the database :: [IN-PROGRESS]
2023-08-29 17:08:22 - ERROR - [create_app.py : check_database_connectivity - 246] :: Current Connection status set to :: False
2023-08-29 17:08:22 - INFO - [create_app.py : check_db_connectivity_and_retry - 230] :: Going for retry .. RETRY_INTERVAL :: 5 sec
2023-08-29 17:08:27 - INFO - [create_app.py : check_database_connectivity - 235] :: Current Connection status set to :: False for the service :: authtoken
2023-08-29 17:08:27 - INFO - [create_app.py : check_database_connectivity - 236] :: Trying to establish the connection to the database :: [IN-PROGRESS]
2023-08-29 17:08:27 - ERROR - [create_app.py : check_database_connectivity - 246] :: Current Connection status set to :: False
2023-08-29 17:08:27 - INFO - [create_app.py : check_db_connectivity_and_retry - 230] :: Going for retry .. RETRY_INTERVAL :: 5 sec
2023-08-29 17:08:32 - INFO - [create_app.py : check_database_connectivity - 235] :: Current Connection status set to :: False for the service :: authtoken
2023-08-29 17:08:32 - INFO - [create_app.py : check_database_connectivity - 236] :: Trying to establish the connection to the database :: [IN-PROGRESS]
2023-08-29 17:08:32 - ERROR - [create_app.py : check_database_connectivity - 246] :: Current Connection status set to :: False
2023-08-29 17:08:32 - INFO - [create_app.py : check_db_connectivity_and_retry - 230] :: Going for retry .. RETRY_INTERVAL :: 5 sec
2023-08-29 17:08:37 - INFO - [create_app.py : check_database_connectivity - 235] :: Current Connection status set to :: False for the service :: authtoken
2023-08-29 17:08:37 - INFO - [create_app.py : check_database_connectivity - 236] :: Trying to establish the connection to the database :: [IN-PROGRESS]
2023-08-29 17:08:37 - ERROR - [create_app.py : check_database_connectivity - 246] :: Current Connection status set to :: False
2023-08-29 17:08:37 - INFO - [create_app.py : check_db_connectivity_and_retry - 230] :: Going for retry .. RETRY_INTERVAL :: 5 sec
2023-08-29 17:08:42 - INFO - [create_app.py : check_database_connectivity - 235] :: Current Connection status set to :: False for the service :: authtoken
2023-08-29 17:08:42 - INFO - [create_app.py : check_database_connectivity - 236] :: Trying to establish the connection to the database :: [IN-PROGRESS]
2023-08-29 17:08:42 - ERROR - [create_app.py : check_database_connectivity - 246] :: Current Connection status set to :: False
2023-08-29 17:08:42 - INFO - [create_app.py : check_db_connectivity_and_retry - 230] :: Going for retry .. RETRY_INTERVAL :: 5 sec
2023-08-29 17:08:47 - INFO - [create_app.py : check_database_connectivity - 235] :: Current Connection status set to :: False for the service :: authtoken
2023-08-29 17:08:47 - INFO - [create_app.py : check_database_connectivity - 236] :: Trying to establish the connection to the database :: [IN-PROGRESS]
2023-08-29 17:08:47 - ERROR - [create_app.py : check_database_connectivity - 246] :: Current Connection status set to :: False
2023-08-29 17:08:47 - INFO - [create_app.py : check_db_connectivity_and_retry - 230] :: Going for retry .. RETRY_INTERVAL :: 5 sec
2023-08-29 17:08:52 - INFO - [create_app.py : check_database_connectivity - 235] :: Current Connection status set to :: False for the service :: authtoken
2023-08-29 17:08:52 - INFO - [create_app.py : check_database_connectivity - 236] :: Trying to establish the connection to the database :: [IN-PROGRESS]
2023-08-29 17:08:52 - ERROR - [create_app.py : check_database_connectivity - 246] :: Current Connection status set to :: False
2023-08-29 17:08:52 - INFO - [create_app.py : check_db_connectivity_and_retry - 230] :: Going for retry .. RETRY_INTERVAL :: 5 sec
2023-08-29 17:08:57 - INFO - [create_app.py : check_database_connectivity - 235] :: Current Connection status set to :: False for the service :: authtoken
2023-08-29 17:08:57 - INFO - [create_app.py : check_database_connectivity - 236] :: Trying to establish the connection to the database :: [IN-PROGRESS]
2023-08-29 17:08:58 - ERROR - [create_app.py : check_database_connectivity - 246] :: Current Connection status set to :: False
2023-08-29 17:08:58 - INFO - [create_app.py : check_db_connectivity_and_retry - 230] :: Going for retry .. RETRY_INTERVAL :: 5 sec
2023-08-29 17:09:03 - INFO - [create_app.py : check_database_connectivity - 235] :: Current Connection status set to :: False for the service :: authtoken
2023-08-29 17:09:03 - INFO - [create_app.py : check_database_connectivity - 236] :: Trying to establish the connection to the database :: [IN-PROGRESS]
2023-08-29 17:09:03 - ERROR - [create_app.py : check_database_connectivity - 246] :: Current Connection status set to :: False
2023-08-29 17:09:03 - INFO - [create_app.py : check_db_connectivity_and_retry - 230] :: Going for retry .. RETRY_INTERVAL :: 5 sec
2023-08-29 17:09:08 - INFO - [create_app.py : check_database_connectivity - 235] :: Current Connection status set to :: False for the service :: authtoken
2023-08-29 17:09:08 - INFO - [create_app.py : check_database_connectivity - 236] :: Trying to establish the connection to the database :: [IN-PROGRESS]
2023-08-29 17:09:08 - ERROR - [create_app.py : check_database_connectivity - 246] :: Current Connection status set to :: False
2023-08-29 17:09:08 - INFO - [create_app.py : check_db_connectivity_and_retry - 230] :: Going for retry .. RETRY_INTERVAL :: 5 sec
2023-08-29 17:09:13 - INFO - [create_app.py : check_database_connectivity - 235] :: Current Connection status set to :: False for the service :: authtoken
2023-08-29 17:09:13 - INFO - [create_app.py : check_database_connectivity - 236] :: Trying to establish the connection to the database :: [IN-PROGRESS]
2023-08-29 17:09:13 - ERROR - [create_app.py : check_database_connectivity - 246] :: Current Connection status set to :: False
2023-08-29 17:09:13 - INFO - [create_app.py : check_db_connectivity_and_retry - 230] :: Going for retry .. RETRY_INTERVAL :: 5 sec
2023-08-29 17:09:18 - INFO - [create_app.py : check_database_connectivity - 235] :: Current Connection status set to :: False for the service :: authtoken
2023-08-29 17:09:18 - INFO - [create_app.py : check_database_connectivity - 236] :: Trying to establish the connection to the database :: [IN-PROGRESS]
2023-08-29 17:09:18 - ERROR - [create_app.py : check_database_connectivity - 246] :: Current Connection status set to :: False
2023-08-29 17:09:18 - INFO - [create_app.py : check_db_connectivity_and_retry - 230] :: Going for retry .. RETRY_INTERVAL :: 5 sec
2023-08-29 17:09:23 - INFO - [create_app.py : check_database_connectivity - 235] :: Current Connection status set to :: False for the service :: authtoken
2023-08-29 17:09:23 - INFO - [create_app.py : check_database_connectivity - 236] :: Trying to establish the connection to the database :: [IN-PROGRESS]
2023-08-29 17:09:23 - ERROR - [create_app.py : check_database_connectivity - 246] :: Current Connection status set to :: False
2023-08-29 17:09:23 - INFO - [create_app.py : check_db_connectivity_and_retry - 230] :: Going for retry .. RETRY_INTERVAL :: 5 sec
2023-08-29 17:09:28 - INFO - [create_app.py : check_database_connectivity - 235] :: Current Connection status set to :: False for the service :: authtoken
2023-08-29 17:09:28 - INFO - [create_app.py : check_database_connectivity - 236] :: Trying to establish the connection to the database :: [IN-PROGRESS]
2023-08-29 17:09:28 - ERROR - [create_app.py : check_database_connectivity - 246] :: Current Connection status set to :: False
2023-08-29 17:09:28 - INFO - [create_app.py : check_db_connectivity_and_retry - 230] :: Going for retry .. RETRY_INTERVAL :: 5 sec
2023-08-29 17:09:33 - INFO - [create_app.py : check_database_connectivity - 235] :: Current Connection status set to :: False for the service :: authtoken
2023-08-29 17:09:33 - INFO - [create_app.py : check_database_connectivity - 236] :: Trying to establish the connection to the database :: [IN-PROGRESS]
2023-08-29 17:09:33 - ERROR - [create_app.py : check_database_connectivity - 246] :: Current Connection status set to :: False
2023-08-29 17:09:33 - INFO - [create_app.py : check_db_connectivity_and_retry - 230] :: Going for retry .. RETRY_INTERVAL :: 5 sec
2023-08-29 17:09:38 - INFO - [create_app.py : check_database_connectivity - 235] :: Current Connection status set to :: False for the service :: authtoken
2023-08-29 17:09:38 - INFO - [create_app.py : check_database_connectivity - 236] :: Trying to establish the connection to the database :: [IN-PROGRESS]
2023-08-29 17:09:38 - ERROR - [create_app.py : check_database_connectivity - 246] :: Current Connection status set to :: False
2023-08-29 17:09:38 - INFO - [create_app.py : check_db_connectivity_and_retry - 230] :: Going for retry .. RETRY_INTERVAL :: 5 sec
2023-08-29 17:09:43 - INFO - [create_app.py : check_database_connectivity - 235] :: Current Connection status set to :: False for the service :: authtoken
2023-08-29 17:09:43 - INFO - [create_app.py : check_database_connectivity - 236] :: Trying to establish the connection to the database :: [IN-PROGRESS]
2023-08-29 17:09:43 - ERROR - [create_app.py : check_database_connectivity - 246] :: Current Connection status set to :: False
2023-08-29 17:09:43 - INFO - [create_app.py : check_db_connectivity_and_retry - 230] :: Going for retry .. RETRY_INTERVAL :: 5 sec
2023-08-29 17:09:48 - INFO - [create_app.py : check_database_connectivity - 235] :: Current Connection status set to :: False for the service :: authtoken
2023-08-29 17:09:48 - INFO - [create_app.py : check_database_connectivity - 236] :: Trying to establish the connection to the database :: [IN-PROGRESS]
2023-08-29 17:09:48 - ERROR - [create_app.py : check_database_connectivity - 246] :: Current Connection status set to :: False
2023-08-29 17:09:48 - INFO - [create_app.py : check_db_connectivity_and_retry - 230] :: Going for retry .. RETRY_INTERVAL :: 5 sec
2023-08-29 17:09:53 - INFO - [create_app.py : check_database_connectivity - 235] :: Current Connection status set to :: False for the service :: authtoken
2023-08-29 17:09:53 - INFO - [create_app.py : check_database_connectivity - 236] :: Trying to establish the connection to the database :: [IN-PROGRESS]
2023-08-29 17:09:53 - ERROR - [create_app.py : check_database_connectivity - 246] :: Current Connection status set to :: False
2023-08-29 17:09:53 - INFO - [create_app.py : check_db_connectivity_and_retry - 230] :: Going for retry .. RETRY_INTERVAL :: 5 sec
2023-08-29 17:09:58 - INFO - [create_app.py : check_database_connectivity - 235] :: Current Connection status set to :: False for the service :: authtoken
2023-08-29 17:09:58 - INFO - [create_app.py : check_database_connectivity - 236] :: Trying to establish the connection to the database :: [IN-PROGRESS]
2023-08-29 17:09:58 - ERROR - [create_app.py : check_database_connectivity - 246] :: Current Connection status set to :: False
2023-08-29 17:09:58 - INFO - [create_app.py : check_db_connectivity_and_retry - 230] :: Going for retry .. RETRY_INTERVAL :: 5 sec
2023-08-29 17:10:03 - INFO - [create_app.py : check_database_connectivity - 235] :: Current Connection status set to :: False for the service :: authtoken
2023-08-29 17:10:03 - INFO - [create_app.py : check_database_connectivity - 236] :: Trying to establish the connection to the database :: [IN-PROGRESS]
2023-08-29 17:10:03 - ERROR - [create_app.py : check_database_connectivity - 246] :: Current Connection status set to :: False
2023-08-29 17:10:03 - INFO - [create_app.py : check_db_connectivity_and_retry - 230] :: Going for retry .. RETRY_INTERVAL :: 5 sec
2023-08-29 17:10:08 - INFO - [create_app.py : check_database_connectivity - 235] :: Current Connection status set to :: False for the service :: authtoken
2023-08-29 17:10:08 - INFO - [create_app.py : check_database_connectivity - 236] :: Trying to establish the connection to the database :: [IN-PROGRESS]
2023-08-29 17:10:08 - ERROR - [create_app.py : check_database_connectivity - 246] :: Current Connection status set to :: False
2023-08-29 17:10:08 - INFO - [create_app.py : check_db_connectivity_and_retry - 230] :: Going for retry .. RETRY_INTERVAL :: 5 sec
2023-08-29 17:10:13 - INFO - [create_app.py : check_database_connectivity - 235] :: Current Connection status set to :: False for the service :: authtoken
2023-08-29 17:10:13 - INFO - [create_app.py : check_database_connectivity - 236] :: Trying to establish the connection to the database :: [IN-PROGRESS]
2023-08-29 17:10:13 - ERROR - [create_app.py : check_database_connectivity - 246] :: Current Connection status set to :: False
2023-08-29 17:10:13 - INFO - [create_app.py : check_db_connectivity_and_retry - 230] :: Going for retry .. RETRY_INTERVAL :: 5 sec
2023-08-29 17:10:18 - INFO - [create_app.py : check_database_connectivity - 235] :: Current Connection status set to :: False for the service :: authtoken
2023-08-29 17:10:18 - INFO - [create_app.py : check_database_connectivity - 236] :: Trying to establish the connection to the database :: [IN-PROGRESS]
2023-08-29 17:10:18 - ERROR - [create_app.py : check_database_connectivity - 246] :: Current Connection status set to :: False
2023-08-29 17:10:18 - INFO - [create_app.py : check_db_connectivity_and_retry - 230] :: Going for retry .. RETRY_INTERVAL :: 5 sec
2023-08-29 17:10:23 - INFO - [create_app.py : check_database_connectivity - 235] :: Current Connection status set to :: False for the service :: authtoken
2023-08-29 17:10:23 - INFO - [create_app.py : check_database_connectivity - 236] :: Trying to establish the connection to the database :: [IN-PROGRESS]
2023-08-29 17:10:23 - ERROR - [create_app.py : check_database_connectivity - 246] :: Current Connection status set to :: False
2023-08-29 17:10:23 - INFO - [create_app.py : check_db_connectivity_and_retry - 230] :: Going for retry .. RETRY_INTERVAL :: 5 sec
2023-08-29 17:10:28 - INFO - [create_app.py : check_database_connectivity - 235] :: Current Connection status set to :: False for the service :: authtoken
2023-08-29 17:10:28 - INFO - [create_app.py : check_database_connectivity - 236] :: Trying to establish the connection to the database :: [IN-PROGRESS]
2023-08-29 17:10:28 - ERROR - [create_app.py : check_database_connectivity - 246] :: Current Connection status set to :: False
2023-08-29 17:10:28 - INFO - [create_app.py : check_db_connectivity_and_retry - 230] :: Going for retry .. RETRY_INTERVAL :: 5 sec
2023-08-29 17:10:33 - INFO - [create_app.py : check_database_connectivity - 235] :: Current Connection status set to :: False for the service :: authtoken
2023-08-29 17:10:33 - INFO - [create_app.py : check_database_connectivity - 236] :: Trying to establish the connection to the database :: [IN-PROGRESS]
2023-08-29 17:10:33 - ERROR - [create_app.py : check_database_connectivity - 246] :: Current Connection status set to :: False
2023-08-29 17:10:33 - INFO - [create_app.py : check_db_connectivity_and_retry - 230] :: Going for retry .. RETRY_INTERVAL :: 5 sec
2023-08-29 17:10:38 - INFO - [create_app.py : check_database_connectivity - 235] :: Current Connection status set to :: False for the service :: authtoken
2023-08-29 17:10:38 - INFO - [create_app.py : check_database_connectivity - 236] :: Trying to establish the connection to the database :: [IN-PROGRESS]
2023-08-29 17:10:38 - ERROR - [create_app.py : check_database_connectivity - 246] :: Current Connection status set to :: False
2023-08-29 17:10:38 - INFO - [create_app.py : check_db_connectivity_and_retry - 230] :: Going for retry .. RETRY_INTERVAL :: 5 sec
2023-08-29 17:10:43 - INFO - [create_app.py : check_database_connectivity - 235] :: Current Connection status set to :: False for the service :: authtoken
2023-08-29 17:10:43 - INFO - [create_app.py : check_database_connectivity - 236] :: Trying to establish the connection to the database :: [IN-PROGRESS]
2023-08-29 17:10:43 - ERROR - [create_app.py : check_database_connectivity - 246] :: Current Connection status set to :: False
2023-08-29 17:10:43 - INFO - [create_app.py : check_db_connectivity_and_retry - 230] :: Going for retry .. RETRY_INTERVAL :: 5 sec
2023-08-29 17:10:48 - INFO - [create_app.py : check_database_connectivity - 235] :: Current Connection status set to :: False for the service :: authtoken
2023-08-29 17:10:48 - INFO - [create_app.py : check_database_connectivity - 236] :: Trying to establish the connection to the database :: [IN-PROGRESS]
2023-08-29 17:10:48 - ERROR - [create_app.py : check_database_connectivity - 246] :: Current Connection status set to :: False
2023-08-29 17:10:48 - INFO - [create_app.py : check_db_connectivity_and_retry - 230] :: Going for retry .. RETRY_INTERVAL :: 5 sec
2023-08-29 17:10:53 - INFO - [create_app.py : check_database_connectivity - 235] :: Current Connection status set to :: False for the service :: authtoken
2023-08-29 17:10:53 - INFO - [create_app.py : check_database_connectivity - 236] :: Trying to establish the connection to the database :: [IN-PROGRESS]
2023-08-29 17:10:53 - ERROR - [create_app.py : check_database_connectivity - 246] :: Current Connection status set to :: False
2023-08-29 17:10:53 - INFO - [create_app.py : check_db_connectivity_and_retry - 230] :: Going for retry .. RETRY_INTERVAL :: 5 sec
2023-08-29 17:10:58 - INFO - [create_app.py : check_database_connectivity - 235] :: Current Connection status set to :: False for the service :: authtoken
2023-08-29 17:10:58 - INFO - [create_app.py : check_database_connectivity - 236] :: Trying to establish the connection to the database :: [IN-PROGRESS]
2023-08-29 17:10:58 - ERROR - [create_app.py : check_database_connectivity - 246] :: Current Connection status set to :: False
2023-08-29 17:10:58 - INFO - [create_app.py : check_db_connectivity_and_retry - 230] :: Going for retry .. RETRY_INTERVAL :: 5 sec
2023-08-29 17:11:03 - INFO - [create_app.py : check_database_connectivity - 235] :: Current Connection status set to :: False for the service :: authtoken
2023-08-29 17:11:03 - INFO - [create_app.py : check_database_connectivity - 236] :: Trying to establish the connection to the database :: [IN-PROGRESS]
2023-08-29 17:11:03 - ERROR - [create_app.py : check_database_connectivity - 246] :: Current Connection status set to :: False
2023-08-29 17:11:03 - INFO - [create_app.py : check_db_connectivity_and_retry - 230] :: Going for retry .. RETRY_INTERVAL :: 5 sec
2023-08-29 17:11:08 - INFO - [create_app.py : check_database_connectivity - 235] :: Current Connection status set to :: False for the service :: authtoken
2023-08-29 17:11:08 - INFO - [create_app.py : check_database_connectivity - 236] :: Trying to establish the connection to the database :: [IN-PROGRESS]
2023-08-29 17:11:08 - ERROR - [create_app.py : check_database_connectivity - 246] :: Current Connection status set to :: False
2023-08-29 17:11:08 - INFO - [create_app.py : check_db_connectivity_and_retry - 230] :: Going for retry .. RETRY_INTERVAL :: 5 sec
2023-08-29 17:11:13 - INFO - [create_app.py : check_database_connectivity - 235] :: Current Connection status set to :: False for the service :: authtoken
2023-08-29 17:11:13 - INFO - [create_app.py : check_database_connectivity - 236] :: Trying to establish the connection to the database :: [IN-PROGRESS]
2023-08-29 17:11:13 - ERROR - [create_app.py : check_database_connectivity - 246] :: Current Connection status set to :: False
2023-08-29 17:11:13 - INFO - [create_app.py : check_db_connectivity_and_retry - 230] :: Going for retry .. RETRY_INTERVAL :: 5 sec
2023-08-29 17:11:18 - INFO - [create_app.py : check_database_connectivity - 235] :: Current Connection status set to :: False for the service :: authtoken
2023-08-29 17:11:18 - INFO - [create_app.py : check_database_connectivity - 236] :: Trying to establish the connection to the database :: [IN-PROGRESS]
2023-08-29 17:11:18 - ERROR - [create_app.py : check_database_connectivity - 246] :: Current Connection status set to :: False
2023-08-29 17:11:18 - INFO - [create_app.py : check_db_connectivity_and_retry - 230] :: Going for retry .. RETRY_INTERVAL :: 5 sec
2023-08-29 17:11:23 - INFO - [create_app.py : check_database_connectivity - 235] :: Current Connection status set to :: False for the service :: authtoken
2023-08-29 17:11:23 - INFO - [create_app.py : check_database_connectivity - 236] :: Trying to establish the connection to the database :: [IN-PROGRESS]
2023-08-29 17:11:23 - ERROR - [create_app.py : check_database_connectivity - 246] :: Current Connection status set to :: False
2023-08-29 17:11:23 - INFO - [create_app.py : check_db_connectivity_and_retry - 230] :: Going for retry .. RETRY_INTERVAL :: 5 sec
2023-08-29 17:11:28 - INFO - [create_app.py : check_database_connectivity - 235] :: Current Connection status set to :: False for the service :: authtoken
2023-08-29 17:11:28 - INFO - [create_app.py : check_database_connectivity - 236] :: Trying to establish the connection to the database :: [IN-PROGRESS]
2023-08-29 17:11:28 - ERROR - [create_app.py : check_database_connectivity - 246] :: Current Connection status set to :: False
2023-08-29 17:11:28 - INFO - [create_app.py : check_db_connectivity_and_retry - 230] :: Going for retry .. RETRY_INTERVAL :: 5 sec
2023-08-29 17:11:33 - INFO - [create_app.py : check_database_connectivity - 235] :: Current Connection status set to :: False for the service :: authtoken
2023-08-29 17:11:33 - INFO - [create_app.py : check_database_connectivity - 236] :: Trying to establish the connection to the database :: [IN-PROGRESS]
2023-08-29 17:11:33 - ERROR - [create_app.py : check_database_connectivity - 246] :: Current Connection status set to :: False
2023-08-29 17:11:33 - INFO - [create_app.py : check_db_connectivity_and_retry - 230] :: Going for retry .. RETRY_INTERVAL :: 5 sec
2023-08-29 17:11:38 - INFO - [create_app.py : check_database_connectivity - 235] :: Current Connection status set to :: False for the service :: authtoken
2023-08-29 17:11:38 - INFO - [create_app.py : check_database_connectivity - 236] :: Trying to establish the connection to the database :: [IN-PROGRESS]
2023-08-29 17:11:38 - ERROR - [create_app.py : check_database_connectivity - 246] :: Current Connection status set to :: False
2023-08-29 17:11:38 - INFO - [create_app.py : check_db_connectivity_and_retry - 230] :: Going for retry .. RETRY_INTERVAL :: 5 sec
2023-08-29 17:11:43 - INFO - [create_app.py : check_database_connectivity - 235] :: Current Connection status set to :: False for the service :: authtoken
2023-08-29 17:11:43 - INFO - [create_app.py : check_database_connectivity - 236] :: Trying to establish the connection to the database :: [IN-PROGRESS]
2023-08-29 17:11:43 - ERROR - [create_app.py : check_database_connectivity - 246] :: Current Connection status set to :: False
2023-08-29 17:11:43 - INFO - [create_app.py : check_db_connectivity_and_retry - 230] :: Going for retry .. RETRY_INTERVAL :: 5 sec
2023-08-29 17:11:48 - INFO - [create_app.py : check_database_connectivity - 235] :: Current Connection status set to :: False for the service :: authtoken
2023-08-29 17:11:48 - INFO - [create_app.py : check_database_connectivity - 236] :: Trying to establish the connection to the database :: [IN-PROGRESS]
2023-08-29 17:11:48 - ERROR - [create_app.py : check_database_connectivity - 246] :: Current Connection status set to :: False
2023-08-29 17:11:48 - INFO - [create_app.py : check_db_connectivity_and_retry - 230] :: Going for retry .. RETRY_INTERVAL :: 5 sec
2023-08-29 17:11:53 - INFO - [create_app.py : check_database_connectivity - 235] :: Current Connection status set to :: False for the service :: authtoken
2023-08-29 17:11:53 - INFO - [create_app.py : check_database_connectivity - 236] :: Trying to establish the connection to the database :: [IN-PROGRESS]
2023-08-29 17:11:53 - ERROR - [create_app.py : check_database_connectivity - 246] :: Current Connection status set to :: False
2023-08-29 17:11:53 - INFO - [create_app.py : check_db_connectivity_and_retry - 230] :: Going for retry .. RETRY_INTERVAL :: 5 sec
2023-08-29 17:11:58 - INFO - [create_app.py : check_database_connectivity - 235] :: Current Connection status set to :: False for the service :: authtoken
2023-08-29 17:11:58 - INFO - [create_app.py : check_database_connectivity - 236] :: Trying to establish the connection to the database :: [IN-PROGRESS]
2023-08-29 17:11:58 - ERROR - [create_app.py : check_database_connectivity - 246] :: Current Connection status set to :: False
2023-08-29 17:11:58 - INFO - [create_app.py : check_db_connectivity_and_retry - 230] :: Going for retry .. RETRY_INTERVAL :: 5 sec
2023-08-29 17:12:03 - INFO - [create_app.py : check_database_connectivity - 235] :: Current Connection status set to :: False for the service :: authtoken
2023-08-29 17:12:03 - INFO - [create_app.py : check_database_connectivity - 236] :: Trying to establish the connection to the database :: [IN-PROGRESS]
2023-08-29 17:12:03 - ERROR - [create_app.py : check_database_connectivity - 246] :: Current Connection status set to :: False
2023-08-29 17:12:03 - INFO - [create_app.py : check_db_connectivity_and_retry - 230] :: Going for retry .. RETRY_INTERVAL :: 5 sec
2023-08-29 17:12:08 - INFO - [create_app.py : check_database_connectivity - 235] :: Current Connection status set to :: False for the service :: authtoken
2023-08-29 17:12:08 - INFO - [create_app.py : check_database_connectivity - 236] :: Trying to establish the connection to the database :: [IN-PROGRESS]
2023-08-29 17:12:08 - ERROR - [create_app.py : check_database_connectivity - 246] :: Current Connection status set to :: False
2023-08-29 17:12:08 - INFO - [create_app.py : check_db_connectivity_and_retry - 230] :: Going for retry .. RETRY_INTERVAL :: 5 sec
2023-08-29 17:12:13 - INFO - [create_app.py : check_database_connectivity - 235] :: Current Connection status set to :: False for the service :: authtoken
2023-08-29 17:12:13 - INFO - [create_app.py : check_database_connectivity - 236] :: Trying to establish the connection to the database :: [IN-PROGRESS]
2023-08-29 17:12:13 - ERROR - [create_app.py : check_database_connectivity - 246] :: Current Connection status set to :: False
2023-08-29 17:12:13 - INFO - [create_app.py : check_db_connectivity_and_retry - 230] :: Going for retry .. RETRY_INTERVAL :: 5 sec
2023-08-29 17:12:18 - INFO - [create_app.py : check_database_connectivity - 235] :: Current Connection status set to :: False for the service :: authtoken
2023-08-29 17:12:18 - INFO - [create_app.py : check_database_connectivity - 236] :: Trying to establish the connection to the database :: [IN-PROGRESS]
2023-08-29 17:12:18 - ERROR - [create_app.py : check_database_connectivity - 246] :: Current Connection status set to :: False
2023-08-29 17:12:18 - INFO - [create_app.py : check_db_connectivity_and_retry - 230] :: Going for retry .. RETRY_INTERVAL :: 5 sec
2023-08-29 17:12:23 - INFO - [create_app.py : check_database_connectivity - 235] :: Current Connection status set to :: False for the service :: authtoken
2023-08-29 17:12:23 - INFO - [create_app.py : check_database_connectivity - 236] :: Trying to establish the connection to the database :: [IN-PROGRESS]
2023-08-29 17:12:23 - ERROR - [create_app.py : check_database_connectivity - 246] :: Current Connection status set to :: False
2023-08-29 17:12:23 - INFO - [create_app.py : check_db_connectivity_and_retry - 230] :: Going for retry .. RETRY_INTERVAL :: 5 sec
2023-08-29 17:12:28 - INFO - [create_app.py : check_database_connectivity - 235] :: Current Connection status set to :: False for the service :: authtoken
2023-08-29 17:12:28 - INFO - [create_app.py : check_database_connectivity - 236] :: Trying to establish the connection to the database :: [IN-PROGRESS]
2023-08-29 17:12:28 - ERROR - [create_app.py : check_database_connectivity - 246] :: Current Connection status set to :: False
2023-08-29 17:12:28 - INFO - [create_app.py : check_db_connectivity_and_retry - 230] :: Going for retry .. RETRY_INTERVAL :: 5 sec
2023-08-29 17:12:33 - INFO - [create_app.py : check_database_connectivity - 235] :: Current Connection status set to :: False for the service :: authtoken
2023-08-29 17:12:33 - INFO - [create_app.py : check_database_connectivity - 236] :: Trying to establish the connection to the database :: [IN-PROGRESS]
2023-08-29 17:12:33 - ERROR - [create_app.py : check_database_connectivity - 246] :: Current Connection status set to :: False
2023-08-29 17:12:33 - INFO - [create_app.py : check_db_connectivity_and_retry - 230] :: Going for retry .. RETRY_INTERVAL :: 5 sec
2023-08-29 17:12:38 - INFO - [create_app.py : check_database_connectivity - 235] :: Current Connection status set to :: False for the service :: authtoken
2023-08-29 17:12:38 - INFO - [create_app.py : check_database_connectivity - 236] :: Trying to establish the connection to the database :: [IN-PROGRESS]
2023-08-29 17:12:38 - ERROR - [create_app.py : check_database_connectivity - 246] :: Current Connection status set to :: False
2023-08-29 17:12:38 - INFO - [create_app.py : check_db_connectivity_and_retry - 230] :: Going for retry .. RETRY_INTERVAL :: 5 sec
2023-08-29 17:12:43 - INFO - [create_app.py : check_database_connectivity - 235] :: Current Connection status set to :: False for the service :: authtoken
2023-08-29 17:12:43 - INFO - [create_app.py : check_database_connectivity - 236] :: Trying to establish the connection to the database :: [IN-PROGRESS]
2023-08-29 17:12:43 - ERROR - [create_app.py : check_database_connectivity - 246] :: Current Connection status set to :: False
2023-08-29 17:12:43 - INFO - [create_app.py : check_db_connectivity_and_retry - 230] :: Going for retry .. RETRY_INTERVAL :: 5 sec
